<?xml version="1.0"?>
<robot xmlns:xacro="http://www.ros.org/wiki/xacro"> 
	<!--xacro:include filename="$(find rb1_base_description)/urdf/bases/rb1_elevator.gazebo.xacro" /-->

	<xacro:macro name="elevator_platform" params="parent hq *origin">
	<!-- PARAMS: -->
	<!-- name : name of the link: -->
	<!-- hq: selects model in high quality (.dae) -->

	<!-- ELEVATOR_BASE_LINK -->
	<joint name="elevator_base_joint" type="fixed">
		<parent link="${parent}"/>
		<child link="elevator_base_link"/>
		<xacro:insert_block name="origin" />
	</joint> 
	
	<link name="elevator_base_link">
		<!--inertial>
			<mass value="25.0" />
			<origin xyz="0 0 0" />
			<inertia	ixx="0.007" ixy="0.0"  ixz="0.0"
						iyy="0.007"  iyz="0.0"
						izz="0.78125"/>
		</inertial-->
		<visual>
			<origin xyz="0 0 0" rpy="0 0 0" />
			<xacro:if value="${hq}">
				<geometry>
					<mesh filename="package://rb1_base_description/meshes/elevator/rb1_elevator_base.dae"/>
				</geometry>
			</xacro:if>
			<xacro:unless value="${hq}">
				<geometry>
					<mesh filename="package://rb1_base_description/meshes/elevator/rb1_elevator_base.stl"/>
				</geometry>
			</xacro:unless>
			<material name="darkgrey">
				<color rgba="0.1 0.1 0.1 1"/>
			</material>
		</visual>  
		<collision>
			<origin xyz="0 0 0" rpy="0 0 0 " />
			<geometry>
				<mesh filename="package://rb1_base_description/meshes/elevator/rb1_elevator_base.dae"/>
			</geometry>
		</collision>
	</link>

	<!-- ELEVATOR PLATFORM -->
	<joint name="elevator_platform_joint" type="prismatic">
			<origin xyz="0.0 0.0 0.041" rpy="0 0 0 " />
			<parent link="elevator_base_link"/>
			<child link="elevator_platform_link" />
			<axis xyz="0 0 1"/>
			<limit effort="1.0" lower="0.0" upper="0.034" velocity="0.5"/>
	</joint> 
	<link name="elevator_platform_link">
		<!--inertial>
			<mass value="0.25" />
			<origin xyz="0 0 0" />
			<inertia  ixx="0.00007" ixy="0.0"  ixz="0.0"  iyy="0.00007"  iyz="0.0"  izz="0.0078" />
		</inertial-->
		<visual>
			<origin xyz="0 0 0" rpy="0 0 0" />
			<xacro:if value="${hq}">
				<geometry>
					<mesh filename="package://rb1_base_description/meshes/elevator/rb1_elevator_platform.dae"/>
				</geometry>
			</xacro:if>
			<xacro:unless value="${hq}">
				<geometry>
					<mesh filename="package://rb1_base_description/meshes/elevator/rb1_elevator_platform.stl"/>
				</geometry>
			</xacro:unless>
			<material name="black">
				<color rgba="0.0 0.0 0.0 1"/>
			</material>
		</visual>  
		<collision>
			<origin xyz="0 0 0" rpy="0 0 0 " />
			<geometry>
				<mesh filename="package://rb1_base_description/meshes/elevator/rb1_elevator_platform.dae"/>
			</geometry>
		</collision>
	</link>

	</xacro:macro>
</robot>

